<?xml version="1.0"?><robot name="marshmallow">
	<link name="0">
		<visual>
			<geometry>
				<cylinder length="1.921032959766755" radius="0.9446741148524574"/>
			</geometry>
		</visual>
		<collision>
			<geometry>
				<cylinder length="1.921032959766755" radius="0.9446741148524574"/>
			</geometry>
		</collision>
		<inertial>
			<mass value="5.385781369274571"/>
			<inertia ixx="0.03" iyy="0.03" izz="0.03" ixy="0" ixz="0" iyx="0"/>
		</inertial>
	</link>
	<link name="11">
		<visual>
			<geometry>
				<cylinder length="1.921032959766755" radius="0.9835741466460812"/>
			</geometry>
		</visual>
		<collision>
			<geometry>
				<cylinder length="1.921032959766755" radius="0.9835741466460812"/>
			</geometry>
		</collision>
		<inertial>
			<mass value="5.838467921945025"/>
			<inertia ixx="0.03" iyy="0.03" izz="0.03" ixy="0" ixz="0" iyx="0"/>
		</inertial>
	</link>
	<joint name="11_to_0" type="revolute">
		<parent link="0"/>
		<child link="11"/>
		<axis xyz="0 0 1"/>
		<limit effort="1" upper="-3.1415" lower="3.1415" velocity="1"/>
		<origin rpy="0.0 4.887560096244514 0.0" xyz="0.1623500414245138 0.0 0.1678353627362783"/>
	</joint>
</robot>
